Traceback (most recent call last):
  File "/srv/conda/envs/notebook/lib/python3.8/site-packages/jupyter_cache/executors/utils.py", line 51, in single_nb_execution
    executenb(
  File "/srv/conda/envs/notebook/lib/python3.8/site-packages/nbclient/client.py", line 1107, in execute
    return NotebookClient(nb=nb, resources=resources, km=km, **kwargs).execute()
  File "/srv/conda/envs/notebook/lib/python3.8/site-packages/nbclient/util.py", line 74, in wrapped
    return just_run(coro(*args, **kwargs))
  File "/srv/conda/envs/notebook/lib/python3.8/site-packages/nbclient/util.py", line 53, in just_run
    return loop.run_until_complete(coro)
  File "/srv/conda/envs/notebook/lib/python3.8/asyncio/base_events.py", line 616, in run_until_complete
    return future.result()
  File "/srv/conda/envs/notebook/lib/python3.8/site-packages/nbclient/client.py", line 553, in async_execute
    await self.async_execute_cell(
  File "/srv/conda/envs/notebook/lib/python3.8/site-packages/nbclient/client.py", line 852, in async_execute_cell
    self._check_raise_for_error(cell, exec_reply)
  File "/srv/conda/envs/notebook/lib/python3.8/site-packages/nbclient/client.py", line 760, in _check_raise_for_error
    raise CellExecutionError.from_cell_and_msg(cell, exec_reply_content)
nbclient.exceptions.CellExecutionError: An error occurred while executing the following cell:
------------------
import rioxarray as rxr

url='https://prd-tnm.s3.amazonaws.com/StagedProducts/Elevation/1m/Projects/CO_MesaCo_QL2_UTM12_2016/TIFF/USGS_one_meter_x74y433_CO_MesaCo_QL2_UTM12_2016.tif'

lidar_ds=rxr.open_rasterio(url)
#resample the DTM to ~3m:
scale_factor = 1/3
new_width = int(lidar_ds.rio.width * scale_factor)
new_height = int(lidar_ds.rio.height * scale_factor)

#reproject the horizontal CRS to match ICESat-2
UTM_wgs84_crs=CRS.from_epsg(32612)
lidar_3m = lidar_ds.rio.reproject(
    UTM_wgs84_crs,
    shape=(new_height, new_width),
    resampling=Resampling.bilinear,
)

------------------

[0;31m---------------------------------------------------------------------------[0m
[0;31mNameError[0m                                 Traceback (most recent call last)
[0;32m<ipython-input-22-b3eb936f0579>[0m in [0;36m<module>[0;34m[0m
[1;32m     14[0m     [0mUTM_wgs84_crs[0m[0;34m,[0m[0;34m[0m[0;34m[0m[0m
[1;32m     15[0m     [0mshape[0m[0;34m=[0m[0;34m([0m[0mnew_height[0m[0;34m,[0m [0mnew_width[0m[0;34m)[0m[0;34m,[0m[0;34m[0m[0;34m[0m[0m
[0;32m---> 16[0;31m     [0mresampling[0m[0;34m=[0m[0mResampling[0m[0;34m.[0m[0mbilinear[0m[0;34m,[0m[0;34m[0m[0;34m[0m[0m
[0m[1;32m     17[0m )

[0;31mNameError[0m: name 'Resampling' is not defined
NameError: name 'Resampling' is not defined

