Traceback (most recent call last):
  File "/srv/conda/envs/notebook/lib/python3.8/site-packages/jupyter_cache/executors/utils.py", line 51, in single_nb_execution
    executenb(
  File "/srv/conda/envs/notebook/lib/python3.8/site-packages/nbclient/client.py", line 1107, in execute
    return NotebookClient(nb=nb, resources=resources, km=km, **kwargs).execute()
  File "/srv/conda/envs/notebook/lib/python3.8/site-packages/nbclient/util.py", line 74, in wrapped
    return just_run(coro(*args, **kwargs))
  File "/srv/conda/envs/notebook/lib/python3.8/site-packages/nbclient/util.py", line 53, in just_run
    return loop.run_until_complete(coro)
  File "/srv/conda/envs/notebook/lib/python3.8/asyncio/base_events.py", line 616, in run_until_complete
    return future.result()
  File "/srv/conda/envs/notebook/lib/python3.8/site-packages/nbclient/client.py", line 553, in async_execute
    await self.async_execute_cell(
  File "/srv/conda/envs/notebook/lib/python3.8/site-packages/nbclient/client.py", line 852, in async_execute_cell
    self._check_raise_for_error(cell, exec_reply)
  File "/srv/conda/envs/notebook/lib/python3.8/site-packages/nbclient/client.py", line 760, in _check_raise_for_error
    raise CellExecutionError.from_cell_and_msg(cell, exec_reply_content)
nbclient.exceptions.CellExecutionError: An error occurred while executing the following cell:
------------------
url_list = earthdata_granule_search(product, version, 
                                    bounding_box, timestampsUTC, 
                                    search_time_window, search_time_window_units, 
                                    list_filepath, ext)
# we can print the list of files, but these are also saved to a file
print(url_list)
------------------

[0;31m---------------------------------------------------------------------------[0m
[0;31mFileNotFoundError[0m                         Traceback (most recent call last)
[0;32m<ipython-input-7-0637c3abed7c>[0m in [0;36m<module>[0;34m[0m
[0;32m----> 1[0;31m url_list = earthdata_granule_search(product, version, 
[0m[1;32m      2[0m                                     [0mbounding_box[0m[0;34m,[0m [0mtimestampsUTC[0m[0;34m,[0m[0;34m[0m[0;34m[0m[0m
[1;32m      3[0m                                     [0msearch_time_window[0m[0;34m,[0m [0msearch_time_window_units[0m[0;34m,[0m[0;34m[0m[0;34m[0m[0m
[1;32m      4[0m                                     list_filepath, ext)
[1;32m      5[0m [0;31m# we can print the list of files, but these are also saved to a file[0m[0;34m[0m[0;34m[0m[0;34m[0m[0m

[0;32m~/book/tutorials/thermal-ir/earthdata_api.py[0m in [0;36mearthdata_granule_search[0;34m(product, version, bounding_box, timestampsUTC, search_time_window, search_time_window_units, list_filepath, ext)[0m
[1;32m     83[0m         [0;31m# open a file there to write to[0m[0;34m[0m[0;34m[0m[0;34m[0m[0m
[1;32m     84[0m         [0mprint[0m[0;34m([0m[0;34m'Writing list of URLs to {}'[0m[0;34m.[0m[0mformat[0m[0;34m([0m[0mlist_filepath[0m[0;34m)[0m[0;34m)[0m[0;34m[0m[0;34m[0m[0m
[0;32m---> 85[0;31m         [0;32mwith[0m [0mopen[0m[0;34m([0m[0mlist_filepath[0m[0;34m,[0m [0;34m"w"[0m[0;34m)[0m [0;32mas[0m [0moutput[0m[0;34m:[0m[0;34m[0m[0;34m[0m[0m
[0m[1;32m     86[0m             [0;32mfor[0m [0mrow[0m [0;32min[0m [0mflattened_url_list[0m[0;34m:[0m[0;34m[0m[0;34m[0m[0m
[1;32m     87[0m                 [0;31m# output each url to a separate line in the file[0m[0;34m[0m[0;34m[0m[0;34m[0m[0m

[0;31mFileNotFoundError[0m: [Errno 2] No such file or directory: '/tmp/thermal-ir/aster_download_list.txt'
FileNotFoundError: [Errno 2] No such file or directory: '/tmp/thermal-ir/aster_download_list.txt'

