Traceback (most recent call last):
  File "/srv/conda/envs/notebook/lib/python3.8/site-packages/nbclient/client.py", line 622, in _async_poll_for_reply
    msg = await ensure_async(self.kc.shell_channel.get_msg(timeout=new_timeout))
  File "/srv/conda/envs/notebook/lib/python3.8/site-packages/nbclient/util.py", line 85, in ensure_async
    result = await obj
  File "/srv/conda/envs/notebook/lib/python3.8/site-packages/jupyter_client/asynchronous/channels.py", line 48, in get_msg
    raise Empty
_queue.Empty

During handling of the above exception, another exception occurred:

Traceback (most recent call last):
  File "/srv/conda/envs/notebook/lib/python3.8/site-packages/jupyter_cache/executors/utils.py", line 51, in single_nb_execution
    executenb(
  File "/srv/conda/envs/notebook/lib/python3.8/site-packages/nbclient/client.py", line 1107, in execute
    return NotebookClient(nb=nb, resources=resources, km=km, **kwargs).execute()
  File "/srv/conda/envs/notebook/lib/python3.8/site-packages/nbclient/util.py", line 74, in wrapped
    return just_run(coro(*args, **kwargs))
  File "/srv/conda/envs/notebook/lib/python3.8/site-packages/nbclient/util.py", line 53, in just_run
    return loop.run_until_complete(coro)
  File "/srv/conda/envs/notebook/lib/python3.8/asyncio/base_events.py", line 616, in run_until_complete
    return future.result()
  File "/srv/conda/envs/notebook/lib/python3.8/site-packages/nbclient/client.py", line 553, in async_execute
    await self.async_execute_cell(
  File "/srv/conda/envs/notebook/lib/python3.8/site-packages/nbclient/client.py", line 836, in async_execute_cell
    exec_reply = await self.task_poll_for_reply
  File "/srv/conda/envs/notebook/lib/python3.8/site-packages/nbclient/client.py", line 646, in _async_poll_for_reply
    await self._async_handle_timeout(timeout, cell)
  File "/srv/conda/envs/notebook/lib/python3.8/site-packages/nbclient/client.py", line 696, in _async_handle_timeout
    raise CellTimeoutError.error_from_timeout_and_cell(
nbclient.exceptions.CellTimeoutError: A cell timed out while it was being executed, after 300 seconds.
The message was: Cell execution timed out.
Here is a preview of the cell contents:
-------------------
['%%time ', '', "files = ['https://datapool.asf.alaska.edu/INTERFEROMETRY_GRD/UA/grmesa_27416_20003-028_20005-007_0011d_s01_L090_01_int_grd.zip',", "        'https://datapool.asf.alaska.edu/AMPLITUDE_GRD/UA/grmesa_27416_20003-028_20005-007_0011d_s01_L090_01_amp_grd.zip']", '    ']
...
['        cmd = "wget -q {0} --user={1} --password={2} -P {3} -nc".format(file, ASF_USER, ASF_PASS, data_dir)', '        os.system(cmd)', '    else:', '        print(filename + " already exists. Skipping download ..")', 'print("done")']
-------------------

